---
title: Item 9. try-finally보다는 try-with-resources를 사용하라
categories: [Effective-Java]
tags: [try-with-resources]
toc: true

date: 2022-05-12
last_modified_at: 2022-05-12
---

## 1. 들어가기

Java의 라이브러리는 close 메서드를 호출해 직접 닫아줘야 하는 자원들이 많습니다.

대표적으로 InputStream, OutputStream, java.sql.Connection 등이 있습니다.

하지만, 클라이언트에서 이를 놓치기 쉬워 성능 문제로 이어지곤 합니다.

그렇다면 어떤 방법으로 이를 해결할 수 있는지 알아봅시다.

## 2. try-finally

전통적인 방법으로 try-finally 문을 사용했습니다.

### 2-1. 사용법

먼저, try-finally 문의 사용법에 대해 알아봅시다.

```java
    InputStream input = new FileInputStream("test.txt");
    try {
        // 예외처리할 코드
    } finally {
        input.close();
    }
```

try-finally 문의 사용법은 매우 간단합니다.

try 문 안에 예외처리할 코드를 넣고, finally 문에서는 사용한 자원들을 닫아주면 끝입니다.

### 2-2. 문제점

매우 간단하고 아무 문제 없어 보이는 try-finally 문에는 문제점들이 있습니다.

예시를 통해 알아보겠습니다.

```java
    InputStream input1 = new FileInputStream("test1.txt");
    try {
        InputStream input2 = null;
        try {
            input2 = new FileInputStream("test2.txt");
        } finally {
            input2.close();
        }
    } finally {
        input1.close();
    }
```

어떠신가요?

뭔가, 코드가 지저분해보이지 않나요?

try-finally 문은 닫아줘야하는 자원이 하나일 때는 깔끔해 보이지만,

여러 개일 경우 코드가 매우 지저분해보여 가독성이 떨어지는 문제점이 있습니다.

가독성 외에도 또 하나의 문제점이 있는데 이것 또한 예시를 통해 알아보겠습니다.

```java
/* Exception */
    public class FirstException extends Exception {}
    public class SecondException extends Exception {}

/* Resource */
    public class TestResource implements AutoCloseable {
        public void doSomething() throws FirstException {
            System.out.println("Do Something");
            throw new FirstException();
        }

        @Override
        public void close() throws SecondException {
            System.out.println("Close");
            throw new SecondException();
        }
    }

/* Client */
    TestResource resource = new TestResource();
    try {
        resource.doSomething();
    } finally {
        resource.close();
    }
```

doSomething 메서드는 FirstException을 발생시키고,

close 메서드는 SecondException을 발생시킵니다.

이를 실행하면 어떤 결과가 나올까요?

분명, 많은 분들이 FirstException 예외가 발생한 후, SecondException 발생하리라 짐작할 것입니다.

하지만 실제 결과는 다음과 같습니다.

```
    Do Something
    Close
    Exception in thread "main" Main$SecondException
        at Main$TestResource.close(Main.java:19)
        at Main.main(Main.java:28)
```

"Do Something"이 출력 값으로 나온 것을 보아 분명, doSomething 메서드를 호출했는데

FirstException 예외는 출력되지 않고 SecondException 예외만 출력된 것을 볼 수 있습니다.

이는 SecondException 예외가 FirstException 예외를 완전히 집어삼켜버린 문제로

스택 추적 내역에 FirstException 예외가 남지 않아

실제 시스템에서의 디버깅을 몹시 어렵게 하는 문제점이 있습니다.

그럼 도저히 방법은 없는걸까요?

이를 보완하기 위해 Java 7의 try-with-resources 문을 사용하기 시작했습니다.

## 3. try-with-resources

(작성중...)